<?xml version="1.0" ?>
<sdf version="1.5">
  <model name="robot">
    <pose>0 0 0.180 0 0 0</pose>
    <static>false</static>
    <link name="base_link">
      <inertial>
        <mass>14.0</mass>
        <inertia>
          <!-- http://en.wikipedia.org/wiki/List_of_moment_of_inertia_tensors
          MATLAB:
          m=14; h=0.19; w=0.4; d=0.5; 
          ixx = 1/12*m*(h^2+d^2)
          iyy = 1/12*m*(w^2+d^2) 
          izz = 1/12*m*(h^2+d^2) 
          -->
          <ixx>0.147116667</ixx>
          <ixy>0.0</ixy>
          <ixz>0.0</ixz>
          <iyy>0.334951167</iyy>
          <iyz>0.0</iyz>
          <izz>0.3978345</izz>
        </inertia>
      </inertial>
      <collision name="collision1">
        <geometry>
          <box>
            <size>0.501 0.300 0.19</size>
          </box>
        </geometry>
      </collision>
      <visual name="visual1">
        <geometry>
          <mesh>
            <uri>model://chassis.dae</uri>
          </mesh>
        </geometry>
      </visual>
    </link>
    <link name="right_front_wheel">
      <pose>0.125 -0.201 -0.06 1.5707 0 0</pose>

      <inertial>
        <mass>1.5</mass>
        <inertia>
          <ixx>0.005240625</ixx>
          <iyy>0.005240625</iyy>
          <izz>0.009075</izz>
          <ixy>0</ixy>
          <ixz>0</ixz>
          <iyz>0</iyz>
        </inertia>
      </inertial>

      <collision name="collision">
        <geometry>
          <cylinder>
            <radius>0.110</radius>
            <length>0.075</length>
          </cylinder>
        </geometry>
        <surface>
          <friction>
            <ode>
              <mu>1</mu>
              <mu2>1</mu2>
<!--              <slip1>0.5</slip1>
              <slip2>0</slip2> -->
            </ode>
          </friction>
        </surface>
      </collision>
      <visual name="visual">
        <geometry>
          <mesh>
            <uri>model://wheel.dae</uri>
          </mesh>
        </geometry>
      </visual>
    </link>
    <link name="left_front_wheel">
      <pose>0.125 0.201 -0.06 1.5707 0 0</pose>

      <inertial>
        <mass>1.5</mass>
        <inertia>
          <ixx>0.005240625</ixx>
          <iyy>0.005240625</iyy>
          <izz>0.009075</izz>
          <ixy>0</ixy>
          <ixz>0</ixz>
          <iyz>0</iyz>
        </inertia>
      </inertial>

      <collision name="collision">
        <geometry>
          <cylinder>
            <radius>0.110</radius>
            <length>0.075</length>
          </cylinder>
        </geometry>
        <surface>
          <friction>
            <ode>
              <mu>1</mu>
              <mu2>1</mu2>
<!--              <slip1>0.5</slip1>
              <slip2>0</slip2> -->
            </ode>
          </friction>
        </surface>
      </collision>
      <visual name="visual">
        <geometry>
          <mesh>
            <uri>model://wheel.dae</uri>
          </mesh>
        </geometry>
      </visual>
    </link>
    <link name="right_rear_wheel">
      <pose>-0.125 -0.201 -0.06 1.5707 0 0</pose>

      <inertial>
        <mass>1.5</mass>
        <inertia>
          <ixx>0.005240625</ixx>
          <iyy>0.005240625</iyy>
          <izz>0.009075</izz>
          <ixy>0</ixy>
          <ixz>0</ixz>
          <iyz>0</iyz>
        </inertia>
      </inertial>

      <collision name="collision">
        <geometry>
          <cylinder>
            <radius>0.110</radius>
            <length>0.075</length>
          </cylinder>
        </geometry>
        <surface>
          <friction>
            <ode>
              <mu>1</mu>
              <mu2>1</mu2>
<!--              <slip1>0.5</slip1>
              <slip2>0</slip2> -->
            </ode>
          </friction>
        </surface>
      </collision>
      <visual name="visual">
        <geometry>
          <mesh>
            <uri>model://wheel.dae</uri>
          </mesh>
        </geometry>
      </visual>
    </link>
    <link name="left_rear_wheel">
      <pose>-0.125 0.201 -0.06 1.5707 0 0</pose>

      <inertial>
        <mass>1.5</mass>
        <inertia>
          <ixx>0.005240625</ixx>
          <iyy>0.005240625</iyy>
          <izz>0.009075</izz>
          <ixy>0</ixy>
          <ixz>0</ixz>
          <iyz>0</iyz>
        </inertia>
      </inertial>

      <collision name="collision">
        <geometry>
          <cylinder>
            <radius>0.110</radius>
            <length>0.075</length>
          </cylinder>
        </geometry>
        <surface>
          <friction>
            <ode>
              <mu>1</mu>
              <mu2>1</mu2>
<!--              <slip1>0.5</slip1>
              <slip2>0</slip2> -->
            </ode>
          </friction>
        </surface>
      </collision>
      <visual name="visual">
        <geometry>
          <mesh>
            <uri>model://wheel.dae</uri>
          </mesh>
        </geometry>
      </visual>
    </link>
    <joint type="revolute" name="right_front">
      <pose>0 0 0 0 0 0</pose>
      <child>right_front_wheel</child>
      <parent>base_link</parent>
      <axis>
        <xyz>0 1 0</xyz>
        <use_parent_model_frame>true</use_parent_model_frame>
      </axis>
    </joint>
    <joint type="revolute" name="right_rear">
      <pose>0 0 0 0 0 0</pose>
      <child>right_rear_wheel</child>
      <parent>base_link</parent>
      <axis>
        <xyz>0 1 0</xyz>
        <use_parent_model_frame>true</use_parent_model_frame>
      </axis>
    </joint>
    <joint type="revolute" name="left_front">
      <pose>0 0 0 0 0 0</pose>
      <child>left_front_wheel</child>
      <parent>base_link</parent>
      <axis>
        <xyz>0 1 0</xyz>
        <use_parent_model_frame>true</use_parent_model_frame>
      </axis>
    </joint>
    <joint type="revolute" name="left_rear">
      <pose>0 0 0 0 0 0</pose>
      <child>left_rear_wheel</child>
      <parent>base_link</parent>
      <axis>
        <xyz>0 1 0</xyz>
        <use_parent_model_frame>true</use_parent_model_frame>
      </axis>
    </joint>

<!-- DEPTH CAMERA-->
    <link name="camera_link">
      <pose>0.1 0 0.15 0 0 0</pose>
      <inertial>
        <mass>0.1</mass>
      </inertial>
      <collision name="collision">
        <geometry>
          <box>
            <size>0.073000 0.276000 0.072000</size>
          </box>
        </geometry>
      </collision>
      <visual name="visual">
        <geometry>
          <mesh>
            <uri>model://kinect.dae</uri>
          </mesh>
        </geometry>
      </visual>
      <sensor name="camera" type="depth">
        <update_rate>100</update_rate>
	<visualize>false</visualize>
        <camera>
          <horizontal_fov>1.047198</horizontal_fov>
          <image>
            <width>640</width>
            <height>480</height>
            <format>R8G8B8</format>
          </image>
          <clip>
            <near>0.05</near>
            <far>15</far>
          </clip>
        </camera>
	<plugin name="camera_plugin" filename="libgazebo_ros_openni_kinect.so">
          <alwaysOn>true</alwaysOn>
	  <updateRate>100.0</updateRate>
	  <baseline>0.2</baseline>    
          <cameraName>camera</cameraName>
          <imageTopicName>rgb/image_raw</imageTopicName>
          <cameraInfoTopicName>rgb/camera_info</cameraInfoTopicName>
          <depthImageTopicName>depth/image_raw</depthImageTopicName>
          <depthImageCameraInfoTopicName>depth/camera_info</depthImageCameraInfoTopicName>
          <pointCloudTopicName>depth/points</pointCloudTopicName>
          <frameName>depth_link</frameName>
          <pointCloudCutoff>0.5</pointCloudCutoff>
          <pointCloudCutoffMax>3.5</pointCloudCutoffMax>
	  <hackBaseline>0.07</hackBaseline>
          <distortionK1>0</distortionK1>
          <distortionK2>0</distortionK2>
          <distortionK3>0</distortionK3>
          <distortionT1>0</distortionT1>
          <distortionT2>0</distortionT2>
          <CxPrime>0</CxPrime>
          <Cx>0</Cx>
          <Cy>0</Cy>
          <focalLength>0</focalLength>
        </plugin>
      </sensor>
    </link>

    <joint name="camera_joint" type="fixed">
      <parent>base_link</parent>
      <child>camera_link</child>
      <pose>0 0 0 0 0 0</pose>
    </joint>

    <joint name="depth_joint" type="fixed">
      <parent>camera_link</parent>
      <child>depth_link</child>
      <pose>0 0 0 -1.58 0 -1.58</pose>
    </joint>

    <!-- CONTROLLERS -->
    <plugin name="skid_steer_drive_controller" 
            filename="libgazebo_ros_skid_steer_drive.so">
      <updateRate>100.0</updateRate>
      <leftFrontJoint>left_front</leftFrontJoint>
      <rightFrontJoint>right_front</rightFrontJoint>
      <leftRearJoint>left_rear</leftRearJoint>
      <rightRearJoint>right_rear</rightRearJoint>
      <wheelSeparation>0.4</wheelSeparation>
      <wheelDiameter>0.215</wheelDiameter>
      <robotBaseFrame>base_link</robotBaseFrame>
      <torque>200</torque>
      <commandTopic>cmd_vel</commandTopic>
      <odometryTopic>odom</odometryTopic>
      <odometryFrame>odom</odometryFrame>
      <broadcastTF>true</broadcastTF>
    </plugin>
    
    <!-- Original libDSkidSteerDrivePlugin for sample
    <plugin name="SkidSteerDrivePlugin" filename="libSkidSteerDrivePlugin.so">
      <right_front>right_front</right_front>
      <right_rear>right_rear</right_rear>
      <left_front>left_front</left_front>
      <left_rear>left_rear</left_rear>
      <MaxForce>5.0</MaxForce>
    </plugin>   -->
<!--
    <plugin name="gazebo_ros_control" filename="libgazebo_ros_control.so">-->
<!--      <robotParam>robot/robot_description</robotParam> -->
<!--      <robotSimType>gazebo_ros_control/DefaultRobotHWSim</robotSimType>
    </plugin>-->

  </model>
</sdf>

